Workbook

Sheet 갑지
A1: 견 적 서
A3: TO : | F3: =TODAY() -> 45511
A5: 工事名(PROJECT) :
A7: 金 額(AMOUNT) : | C7: 一일금 | D7: =NUMBERSTRING(D8,1)&"원정-부가세 별도" -> 일억일천팔백사십팔만원정-부가세 별도
C8: ( | D8: =' 갑지-1'!L22 -> 118480000 | E8: )
A10: 貴社의 사양에 衣하여 下記內容과 같이 見積합니다.
A13: ◈ 비 고 (REMARK)
A14: 1. | B14: 부가세 별도
A15: 2. | B15: 견적외 별도
A16: 3.
A17: 4.
A18: 5.
A19: 6.
A20: 7.
G21: MOHAE DESIGN
G22: 경기 용인시 수지구 신봉동 242-28
G23: Tel : 031-272-2724

Sheet  갑지-1
A1: PROJECT: 김은경 고객님 가견적_필름
A3: TO :
A4: No | B4: Description | C4: Size | D4: Spec. | E4: Unit | F4: Q'ty | G4: Material | I4: Labour | K4: Total | M4: Remark
G5: Unit Price | H5: Amount | I5: Unit Price | J5: Amount | K5: Unit Price | L5: Amount
A6: *
A7: A. | B7: 인테리어 공사 | E7: 식 | F7: 1 | H7: ='117동 204호'!H40 -> 49232500 | J7: ='117동 204호'!J40 -> 42152800 | L7: ='117동 204호'!L40 -> 91425300
A8: B. | B8: 가설 공사 | E8: 식 | F8: 1 | H8: ='117동 204호'!H26 -> 3000000 | J8: ='117동 204호'!J26 -> 680000 | L8: ='117동 204호'!L26 -> 3680000
B10: 직접공사비 계 | H10: ='117동 204호'!H10 -> 52232500 | J10: ='117동 204호'!J10 -> 42832800 | L10: ='117동 204호'!L10 -> 95105300
A12: * | B12: 디자인 컨설팅 | E12: 0.05 | F12: 1 | L12: =L10*E12 -> 4755265
A13: * | B13: 감리 | E13: 0.03 | F13: 1 | L13: =L10*E13 -> 2853159
A14: * | B14: 공과잡비 | E14: 0.04 | F14: 1 | L14: =L10*E14 -> 3804212
A15: * | B15: 기업이윤 | E15: 0.1 | F15: 1 | L15: =L10*E15 -> 9510530
A16: * | B16: 고용 산재 보험 | E16: 0.03 | F16: 1 | L16: =L10*E16 -> 2853159
B19: 간접공사비 계 | L19: =SUM(L12:L18) -> 23776325
K21: 절사 | L21: 401625
B22: 공사비 계 | L22: =L10+L19+L20-L21 -> 118480000 | M22: VAT 별도
A28: * | B28: 참고사항
A29: - | B29: 부가세 별도
A30: - | B30: 견적 외 별도

Sheet 117동 204호
A1: PROJECT:
A2: No | B2: Description | C2: Product & Size | D2: Location & Spec. | E2: Unit | F2: Q'ty | G2: Material | I2: Labour | K2: Total | M2: Remark
G3: Unit Price | H3: Amount | I3: Unit Price | J3: Amount | K3: Unit Price | L3: Amount | O3: 물량 산출
A6: *
A7: A. | B7: =B12 -> 가설공사 | E7: 식 | F7: 1 | H7: =H26 -> 3000000 | J7: =J26 -> 680000 | L7: =L26 -> 3680000
A8: B. | B8: =B28 -> 인테리어 공사 | E8: 식 | F8: 1 | H8: =H40 -> 49232500 | J8: =J40 -> 42152800 | L8: =L40 -> 91425300
B10: 직접공사비 계 | H10: =SUM(H7:H9) -> 52232500 | J10: =SUM(J7:J9) -> 42832800 | L10: =SUM(L7:L9) -> 95105300
A12: A. | B12: 가설공사 | C12: v
A13: 직영 | B13: 현장보양 및 현장 정리 | E13: M2 | F13: 0 | G13: 2000 | H13: =F13*G13 -> 0 | I13: 8000 | J13: =F13*I13 -> 0 | K13: =G13+I13 -> 10000 | L13: =F13*K13 -> 0
A14: 직영 | B14: 소운반 | E14: 인 | F14: 4 | G14: 0 | H14: =F14*G14 -> 0 | I14: 170000 | J14: =F14*I14 -> 680000 | K14: =G14+I14 -> 170000 | L14: =F14*K14 -> 680000
A15: 사다리차 | B15: 대운반 | C15: 5TON | E15: 대 | F15: 0 | G15: 400000 | H15: =F15*G15 -> 0 | I15: 0 | J15: =F15*I15 -> 0 | K15: =G15+I15 -> 400000 | L15: =F15*K15 -> 0
A16: 허가 | B16: 공사동의서 및 행위허가 | D16: 소견서 2장추가 | E16: 식 | F16: 1 | G16: 650000 | H16: =F16*G16 -> 650000 | I16: 0 | J16: =F16*I16 -> 0 | K16: =G16+I16 -> 650000 | L16: =F16*K16 -> 650000
A17: 가설 | B17: 엘리베이터 보양 | D17: 동선보양 | E17: 개소 | F17: 1 | G17: 350000 | H17: =F17*G17 -> 350000 | I17: 0 | J17: =F17*I17 -> 0 | K17: =G17+I17 -> 350000 | L17: =F17*K17 -> 350000
A18: 가설 | B18: 엘리베이터 사용료 | C18: 관리사무소 고객 직접 납부 | E18: 식 | F18: 0 | G18: 0 | H18: =F18*G18 -> 0 | I18: 0 | J18: =F18*I18 -> 0 | K18: =G18+I18 -> 0 | L18: =F18*K18 -> 0
A19: 도어락 | B19: 디지털 도어락 | C19: 별도 | E19: M2 | F19: 0 | G19: 0 | H19: =F19*G19 -> 0 | I19: 0 | J19: =F19*I19 -> 0 | K19: =G19+I19 -> 0 | L19: =F19*K19 -> 0
A20: 인터폰 | B20: 인터폰 | C20: 별도 | E20: M2
A21: 에어컨 | B21: 에어컨 | C21: 별도 | E21: 식 | F21: 0 | G21: 0 | H21: =F21*G21 -> 0 | I21: 0 | J21: =F21*I21 -> 0 | K21: =G21+I21 -> 0 | L21: =F21*K21 -> 0
A22: 환기 | B22: 전열교환기 | C22: 별도 | E22: 식 | F22: 0 | G22: 0 | H22: =F22*G22 -> 0 | I22: 0 | J22: =F22*I22 -> 0 | K22: =G22+I22 -> 0 | L22: =F22*K22 -> 0 | O22: =(155*0.05) -> 7.75
A23: 폐기물 | B23: 페기물 반출 | C23: 1TON | E23: 대 | F23: 4 | G23: 500000 | H23: =F23*G23 -> 2000000 | I23: 0 | J23: =F23*I23 -> 0 | K23: =G23+I23 -> 500000 | L23: =F23*K23 -> 2000000 | N23: 10평에 1.1대
A24: 입주청소 | B24: 입주청소 | C24: 모해디자인 진행 사항 | D24: 서비스 품목 | E24: PY | F24: 42 | G24: 3000 | H24: =F24*G24 -> 126000 | I24: 15000 | J24: =F24*I24 -> 630000 | K24: =G24+I24 -> 18000 | L24: =F24*K24 -> 756000 | M24: 모해 서비스 진행
B26: 소 계 | H26: =SUM(H13:H23) -> 3000000 | J26: =SUM(J13:J23) -> 680000 | L26: =SUM(L13:L23) -> 3680000
A28: B. | B28: 인테리어 공사
A29: 1. | B29: =B43 -> 철거 / 설비 공사 | E29: 식 | F29: 1 | H29: =H59 -> 3570200 | J29: =J59 -> 8422300 | L29: =L59 -> 11992500 | O29: =H29+J29 -> 11992500
A30: 2. | B30: =B61 -> 필름 공사 | E30: 식 | F30: 1 | H30: =H70 -> 2156300 | J30: =J70 -> 3303000 | L30: =L70 -> 5459300 | O30: =H30+J30 -> 5459300
A31: 3. | B31: =B72 -> 가구 공사 | E31: 식 | F31: 1 | H31: =H108 -> 13644000 | J31: =J108 -> 3210000 | L31: =L108 -> 16854000 | O31: =H31+J31 -> 16854000
A32: 4. | B32: =B110 -> 전기 공사 | E32: 식 | F32: 1 | H32: =H125 -> 4211000 | J32: =J125 -> 4010000 | L32: =L125 -> 8221000 | O32: =H32+J32 -> 8221000
A33: 5. | B33: =B127 -> 화장실 공사 | E33: 식 | F33: 1 | H33: =H163 -> 4958000 | J33: =J163 -> 2790000 | L33: =L163 -> 7788000 | O33: =H33+J33 -> 7748000
A34: 6. | B34: =B165 -> 타일 공사 | E34: 식 | F34: 1 | H34: =H200 -> 2832000 | J34: =J200 -> 4115000 | L34: =L200 -> 6947000 | O34: =H34+J34 -> 6947000
A35: 9. | B35: =B202 -> 도배 공사 | E35: 식 | F35: 1 | H35: =H211 -> 1655500 | J35: =J211 -> 2580000 | L35: =L211 -> 4235500 | O35: =H35+J35 -> 4235500
A36: 10. | B36: =B213 -> 도장 공사 | E36: 식 | F36: 1 | H36: =H221 -> 910000 | J36: =J221 -> 1140000 | L36: =L221 -> 2050000 | O36: =H36+J36 -> 2050000
A37: 11. | B37: =B223 -> 마루 공사 | E37: 식 | F37: 1 | H37: =H231 -> 4305000 | J37: =J231 -> 875000 | L37: =L231 -> 5180000 | O37: =H37+J37 -> 5180000
A38: 12. | B38: =B233 -> 목공사 | E38: 식 | F38: 1 | H38: =H286 -> 10990500 | J38: =J286 -> 11707500 | L38: =L286 -> 22698000 | O38: =H38+J38 -> 22698000
B40: 소 계 | H40: =SUM(H29:H39) -> 49232500 | J40: =SUM(J29:J39) -> 42152800 | L40: =SUM(L29:L39) -> 91425300
A43: 1. | B43: 철거 / 설비 공사 | C43: v
A44: 철거 | B44: 마루 철거 | C44: 거실, 방 전체 | E44: PY | F44: 29 | G44: 8800 | H44: =F44*G44 -> 255200 | I44: 18700 | J44: =F44*I44 -> 542300 | K44: =G44+I44 -> 27500 | L44: =F44*K44 -> 797500
A45: 철거 | B45: 타일 철거 | C45: 현관 | E45: PY | F45: 3 | G45: 15000 | H45: =F45*G45 -> 45000 | I45: 70000 | J45: =F45*I45 -> 210000 | K45: =G45+I45 -> 85000 | L45: =F45*K45 -> 255000
A46: 철거 | B46: 화장실 철거 | C46: 전체 철거 | E46: 식 | F46: 2 | G46: 0 | H46: =F46*G46 -> 0 | I46: 650000 | J46: =F46*I46 -> 1300000 | K46: =G46+I46 -> 650000 | L46: =F46*K46 -> 1300000
A47: 철거 | B47: 본 철거 | E47: M2 | F47: 140 | G47: 8000 | H47: =F47*G47 -> 1120000 | I47: 18000 | J47: =F47*I47 -> 2520000 | K47: =G47+I47 -> 26000 | L47: =F47*K47 -> 3640000
A48: 철거 | B48: 가스관 철거 | E48: 식 | F48: 1 | H48: =F48*G48 -> 0 | I48: 200000 | J48: =F48*I48 -> 200000 | K48: =G48+I48 -> 200000 | L48: =F48*K48 -> 200000
A49: 설비 | B49: 확장 공사 | E49: EA | F49: 4 | G49: 300000 | H49: =F49*G49 -> 1200000 | I49: 500000 | J49: =F49*I49 -> 2000000 | K49: =G49+I49 -> 800000 | L49: =F49*K49 -> 3200000
...
