Workbook

Sheet 갑지
A1: 견 적 서
A3: TO : 정혜경 고객님 | F3: =TODAY() -> 45973
A5: 工事名(PROJECT) : | C5: 진산마을 삼성레미안 5단지 인테리어 공사
A7: 金 額(AMOUNT) : | C7: 一일금 | D7: =NUMBERSTRING(D8,1)&"원정-부가세 별도" -> 일억팔천육백칠만삼천사백구십오원정-부가세 별도
C8: ( | D8: =' 갑지-1'!L26 -> 1.8607349e+08 | E8: )
A10: 貴社의 사양에 依하여 下記內容과 같이 見積합니다.
A13: ◈ 비 고 (REMARK)
A14: 1. | B14: 부가세 별도
A15: 2. | B15: 견적외 별도
A16: 3.
A17: 4.
A18: 5.
A19: 6.
A20: 7.
G21: MOHAE DESIGN
G22: 경기 용인시 수지구 신봉동 242-28
G23: Tel : 031-272-2724

Sheet  갑지-1
A1: PROJECT: 진산마을 삼성레미안 5단지 인테리어 공사
A4: No | B4: Description | C4: Size | D4: Spec. | E4: Unit | F4: Q'ty | G4: Material | I4: Labour | K4: Total | M4: Remark
G5: Unit Price | H5: Amount | I5: Unit Price | J5: Amount | K5: Unit Price | L5: Amount
A6: * | B6: 정혜경 고객님
A7: A. | B7: 재료비 | E7: 식 | F7: 1 | H7: =상세!H10 -> 93413611 | J7: 0 | L7: =H7 -> 93413611
A8: B. | B8: 노무비 | E8: 식 | F8: 1 | H8: 0 | J8: =상세!J10 -> 56594217 | L8: =J8 -> 56594217
B10: 직접공사비 계 | H10: =상세!H10 -> 93413611 | J10: =상세!J10 -> 56594217 | L10: =L8+L7 -> 1.5000783e+08
A12: * | B12: 산재 보험료 | C12: 노무비*3.56% | E12: 0.0356 | F12: 1 | L12: =J10*E12 -> 2014754.1
A13: * | B13: 고용 보험료 | C13: 노무비*1.01% | E13: 0.0101 | F13: 1 | L13: =J10*E13 -> 571601.59
A14: * | B14: 국민건강 보험료 | C14: 노무비*3.545% | E14: 0.03545 | F14: 1 | L14: =J10*E14 -> 2006265
A15: * | B15: 국민연금 보험료 | C15: 노무비*4.5% | E15: 0.045 | F15: 1 | L15: =J10*E15 -> 2546739.7
A16: * | B16: 노인 장기 요양 보험료 | C16: 건강보혐료*12.95% | E16: 0.1295 | F16: 1 | L16: =L14*E16 -> 259811.31
A17: * | B17: 안전관리비 | C17: 직접공사비*3.11% | E17: 0.0311 | F17: 1 | L17: =L10*E17 -> 4665243.4
A18: * | B18: 기타경비 | E18: 0.02 | L18: =L10*E18 -> 3000156.5
A19: * | B19: 공과잡비 | E19: 0.04 | F19: 1 | L19: =L10*E19 -> 6000313.1
A20: * | B20: 기업이윤 | E20: 0.1 | F20: 1 | L20: =L10*E20 -> 15000783
B23: 간접공사비 계 | L23: =SUM(L12:L22) -> 36065668
K25: 절사
B26: 공사비 계 | L26: =L10+L23+L24-L25 -> 1.8607349e+08 | M26: VAT 별도
A32: * | B32: 참고사항
A33: - | B33: 부가세 별도
A34: - | B34: 견적 외 별도

Sheet 상세
A1: PROJECT: 진산마을 삼성레미안 5단지 인테리어 공사
A2: No | B2: Description | C2: Product & Size | D2: Location & Spec. | E2: Unit | F2: Q'ty | G2: Material | I2: Labour | K2: Total | M2: Remark
G3: Unit Price | H3: Amount | I3: Unit Price | J3: Amount | K3: Unit Price | L3: Amount
A6: * | B6: 정혜경 고객님
A7: A. | B7: =B12 -> 가설공사 | E7: 식 | F7: 1 | H7: =H28 -> 12182000 | J7: =J28 -> 2528000 | L7: =L28 -> 14710000
A8: B. | B8: =B30 -> 인테리어 공사 | E8: 식 | F8: 1 | H8: =H41 -> 81231611 | J8: =J41 -> 54066217 | L8: =L41 -> 1.3529783e+08
B10: 직접공사비 계 | H10: =SUM(H7:H9) -> 93413611 | J10: =SUM(J7:J9) -> 56594217 | L10: =SUM(L7:L9) -> 1.5000783e+08
A12: A. | B12: 가설공사
A13: 직영 | B13: 현장보양 및 현장 정리 | E13: M2 | F13: 166 | G13: 2000 | H13: =F13*G13 -> 332000 | I13: 8000 | J13: =F13*I13 -> 1328000 | K13: =G13+I13 -> 10000 | L13: =F13*K13 -> 1660000
A14: 직영 | B14: 소운반 | E14: 인 | F14: 5 | G14: 0 | H14: =F14*G14 -> 0 | I14: 170000 | J14: =F14*I14 -> 850000 | K14: =G14+I14 -> 170000 | L14: =F14*K14 -> 850000
A15: 직영 | B15: 대운반 | C15: 자재 양중 | E15: 대 | F15: 1 | G15: 0 | H15: =F15*G15 -> 0 | I15: 350000 | J15: =F15*I15 -> 350000 | K15: =G15+I15 -> 350000 | L15: =F15*K15 -> 350000
A16: 허가 | B16: 공사동의서 및 행위허가 | C16: 행위허가 | E16: 식 | F16: 1 | G16: 350000 | H16: =F16*G16 -> 350000 | I16: 0 | J16: =F16*I16 -> 0 | K16: =G16+I16 -> 350000 | L16: =F16*K16 -> 350000
A17: 가설 | B17: 엘리베이터 및 공용부 보양 | E17: 개소 | F17: 1 | G17: 200000 | H17: =F17*G17 -> 200000 | I17: 0 | J17: =F17*I17 -> 0 | K17: =G17+I17 -> 200000 | L17: =F17*K17 -> 200000
A18: 에어컨 | B18: 에어컨 | C18: 별도 / LG 시스템에어컨 5대 | E18: 식 | F18: 1 | G18: 0 | H18: =F18*G18 -> 0 | I18: 0 | J18: =F18*I18 -> 0 | K18: =G18+I18 -> 0 | L18: =F18*K18 -> 0
A19: 창호 | B19: 샷시 | C19: 별도 / KCC | E19: 식 | F19: 1 | G19: 0 | H19: =F19*G19 -> 0 | I19: 0 | J19: =F19*I19 -> 0 | K19: =G19+I19 -> 0 | L19: =F19*K19 -> 0
A20: 난방 | B20: 난방배관 교체 | C20: 홈파기 / 분배기 교체 포함 | E20: 식 | F20: 1 | G20: 7300000 | H20: =F20*G20 -> 7300000 | I20: 0 | J20: =F20*I20 -> 0 | K20: =G20+I20 -> 7300000 | L20: =F20*K20 -> 7300000
A21: 보일러 | B21: 개별 보일러 | C21: 경동보일러 / 별도 | E21: 식 | F21: 0
A22: 난방 | B22: 난방배관 교체 | C22: 지역난방 / 분배기 가지관 교체 | E22: 식 | F22: 1 | G22: 1500000 | H22: =F22*G22 -> 1500000 | I22: 0 | J22: =F22*I22 -> 0 | K22: =G22+I22 -> 1500000 | L22: =F22*K22 -> 1500000
A23: 인터폰 | B23: 비디오폰 및 도어락 | C23: 제품 미정 | E23: 식 | F23: 0 | G23: 0 | H23: =F23*G23 -> 0 | I23: 300000 | J23: =F23*I23 -> 0 | K23: =G23+I23 -> 300000 | L23: =F23*K23 -> 0
A24: 환기 | B24: 전열교환기 | C24: 별도 | E24: 식 | F24: 0 | G24: 0 | H24: =F24*G24 -> 0 | I24: 0 | J24: =F24*I24 -> 0 | K24: =G24+I24 -> 0 | L24: =F24*K24 -> 0
A25: 폐기물 | B25: 페기물 반출 | C25: 1TON | E25: 대 | F25: 5 | G25: 500000 | H25: =F25*G25 -> 2500000 | I25: 0 | J25: =F25*I25 -> 0 | K25: =G25+I25 -> 500000 | L25: =F25*K25 -> 2500000
A26: 입주청소 | B26: 입주청소 | C26: 모해디자인 진행 사항 | D26: 서비스 품목 | E26: PY | F26: =F13/3.3 -> 50.30303 | G26: 3000 | H26: =F26*G26 -> 150909.09 | I26: 15000 | J26: =F26*I26 -> 754545.45 | K26: =G26+I26 -> 18000 | L26: =F26*K26 -> 905454.55 | M26: 모해 서비스 진행
B28: 소 계 | H28: =SUM(H13:H25) -> 12182000 | J28: =SUM(J13:J25) -> 2528000 | L28: =SUM(L13:L25) -> 14710000
A30: B. | B30: 인테리어 공사
A31: 1. | B31: =B44 -> 철거 / 설비 공사 | E31: 식 | F31: 1 | H31: =H74 -> 7879454.5 | J31: =J74 -> 13852455 | L31: =L74 -> 21731909
A32: 2. | B32: =B76 -> 필름 공사 | E32: 식 | F32: 1 | H32: =H89 -> 1327050 | J32: =J89 -> 2499450 | L32: =L89 -> 3826500
A33: 3. | B33: =B91 -> 가구 공사 | E33: 식 | F33: 1 | H33: =H183 -> 22570000 | J33: =J183 -> 6106000 | L33: =L183 -> 28676000
A34: 4. | B34: =B185 -> 전기 공사 | E34: 식 | F34: 1 | H34: =H270 -> 5891100 | J34: =J270 -> 4069000 | L34: =L270 -> 9960100
A35: 5. | B35: =B272 -> 화장실 공사 | E35: 식 | F35: 1 | H35: =H322 -> 7698000 | J35: =J322 -> 2340000 | L35: =L322 -> 10038000
A36: 6. | B36: =B324 -> 타일 공사 | E36: 식 | F36: 1 | H36: =H343 -> 3983360 | J36: =J343 -> 5904000 | L36: =L343 -> 9887360
A37: 9. | B37: =B345 -> 도배 공사 | E37: 식 | F37: 1 | H37: =H356 -> 3380280 | J37: =J356 -> 3187200 | L37: =L356 -> 6567480
A38: 10. | B38: =B358 -> 도장 공사 | E38: 식 | F38: 1 | H38: =H363 -> 755000 | J38: =J363 -> 920000 | L38: =L363 -> 1675000
A39: 11. | B39: =B365 -> 마루 공사 | E39: 식 | F39: 1 | H39: =H370 -> 13381818 | J39: =J370 -> 0 | L39: =L370 -> 13381818
A40: 12. | B40: =B372 -> 목공사 | E40: 식 | F40: 1 | H40: =H406 -> 14365548 | J40: =J406 -> 15188112 | L40: =L406 -> 29553660
B41: 소 계 | H41: =SUM(H31:H40) -> 81231611 | J41: =SUM(J31:J40) -> 54066217 | L41: =SUM(L31:L40) -> 1.3529783e+08
A44: 1. | B44: 철거 / 설비 공사
A45: 철거 | B45: 마루 철거 | D45: 거실, 방 전체 | E45: PY | F45: =138/3.3 -> 41.818182 | G45: 3000 | H45: =F45*G45 -> 125454.55 | I45: 25000 | J45: =F45*I45 -> 1045454.5 | K45: =G45+I45 -> 28000 | L45: =F45*K45 -> 1170909.1
A46: 철거 | B46: 타일 철거 | D46: 현관 | E46: M2 | F46: 18 | G46: 15000 | H46: =F46*G46 -> 270000 | I46: 70000 | J46: =F46*I46 -> 1260000 | K46: =G46+I46 -> 85000 | L46: =F46*K46 -> 1530000
A47: 철거 | B47: 화장실 철거 | D47: 전체 철거 | E47: 식 | F47: 2 | G47: 0 | H47: =F47*G47 -> 0 | I47: 650000 | J47: =F47*I47 -> 1300000 | K47: =G47+I47 -> 650000 | L47: =F47*K47 -> 1300000
A48: 철거 | B48: 조적벽체 철거 | D48: 안방,거실 화장실 | E48: 식 | F48: 3 | G48: 20000 | H48: =F48*G48 -> 60000 | I48: 230000 | J48: =F48*I48 -> 690000 | K48: =G48+I48 -> 250000 | L48: =F48*K48 -> 750000
...
