Workbook

Sheet 갑지
A1: 견 적 서
A3: TO : 행당동 금호어울림 | F3: =TODAY() -> 46030
A5: 工事名(PROJECT) : | C5: 행당동 금호어울림
A7: 金 額(AMOUNT) : | C7: 一일금 | D7: =NUMBERSTRING(D8,1)&"원정-부가세 별도" -> 칠천구백일십칠만오천칠백일십오원정-부가세 별도
C8: ( | D8: =' 갑지-1'!L22 -> 79175715 | E8: )
A10: 貴社의 사양에 衣하여 下記內容과 같이 見積합니다.
A13: ◈ 비 고 (REMARK)
A14: 1. | B14: 부가세 별도
A15: 2. | B15: 견적외 별도
A16: 3.
A17: 4.
A18: 5.
A19: 6.
A20: 7.
G21: M.O.A.C
G22: 경기 용인시 수지구 이의동 1221 오렌지 나무 빌딩 3층

Sheet  갑지-1
A1: PROJECT: 행당동 대림아파트
A3: =TODAY() -> 46030
A4: No | B4: Description | C4: Size | D4: Spec. | E4: Unit | F4: Q'ty | G4: Material | I4: Labour | K4: Total | M4: Remark
G5: Unit Price | H5: Amount | I5: Unit Price | J5: Amount | K5: Unit Price | L5: Amount
A6: * | B6: 행당동 대림아파트
A7: A. | B7: 인테리어 공사 | E7: 식 | F7: 1 | H7: =상세!H48 -> 31939500 | J7: =상세!J48 -> 28081000 | L7: =상세!L48 -> 60000500
A8: B. | B8: 가설 공사 | E8: 식 | F8: 1 | H8: =상세!H33 -> 2510000 | J8: =상세!J33 -> 1860000 | L8: =상세!L33 -> 4370000
B10: 직접공사비 계 | H10: =상세!H10 -> 34449500 | J10: =상세!J10 -> 29941000 | L10: =상세!L10 -> 64370500
A12: * | B12: 디자인 컨설팅 | E12: 0.06 | F12: 1 | L12: =L10*E12 -> 3862230
A13: * | B13: 감리 | E13: 0 | F13: 1 | L13: =L10*E13 -> 0
A14: * | B14: 공과잡비 | E14: 0.05 | F14: 1 | L14: =L10*E14 -> 3218525
A15: * | B15: 기업이윤 | E15: 0.1 | F15: 1 | L15: =L10*E15 -> 6437050
A16: * | B16: 산재보험료 외 | E16: 0.02 | F16: 1 | L16: =L10*E16 -> 1287410
B19: 간접공사비 계 | L19: =SUM(L12:L18) -> 14805215
K21: 절사
B22: 공사비 계 | L22: =L10+L19+L20-L21 -> 79175715 | M22: VAT 별도
L23: =L22*1.1 -> 87093286
A28: * | B28: 참고사항
A29: - | B29: 부가세 별도
A30: - | B30: 견적 외 별도

Sheet 상세
A1: PROJECT: 행당동 대림아파트
B2: Description | C2: Product & Size | D2: Location & Spec. | E2: Unit | F2: Q'ty | G2: Material | I2: Labour | K2: Total | M2: Remark
G3: Unit Price | H3: Amount | I3: Unit Price | J3: Amount | K3: Unit Price | L3: Amount | O3: 물량 산출
A6: * | B6: 행당동 대림아파트
A7: A. | B7: =B15 -> 가설공사 | E7: 식 | F7: 1 | H7: =H33 -> 2510000 | J7: =J33 -> 1860000 | L7: =L33 -> 4370000
A8: B. | B8: =B35 -> 인테리어 공사 | E8: 식 | F8: 1 | H8: =H48 -> 31939500 | J8: =J48 -> 28081000 | L8: =L48 -> 60000500
B10: 직접공사비 계 | H10: =SUM(H7:H9) -> 34449500 | J10: =SUM(J7:J9) -> 29941000 | L10: =SUM(L7:L9) -> 64370500
A15: A. | B15: 가설공사
A16: 직영 | B16: 현장 정리 및 자재 양중 | E16: M2 | F16: 105 | G16: 2000 | H16: =F16*G16 -> 210000 | I16: 8000 | J16: =F16*I16 -> 840000 | K16: =G16+I16 -> 10000 | L16: =F16*K16 -> 1050000 | Q16: =93993056/1000000 -> 93.993056
A17: 직영 | B17: 소운반 | E17: 인 | F17: 4 | G17: 0 | H17: =F17*G17 -> 0 | I17: 180000 | J17: =F17*I17 -> 720000 | K17: =G17+I17 -> 180000 | L17: =F17*K17 -> 720000
A18: 사다리차 | B18: 대운반 | C18: 5TON | E18: 대 | F18: 0 | G18: 400000 | H18: =F18*G18 -> 0 | I18: 0 | J18: =F18*I18 -> 0 | K18: =G18+I18 -> 400000 | L18: =F18*K18 -> 0
A19: 허가 | B19: 공사동의서 | E19: 식 | F19: 0 | G19: 200000 | H19: =F19*G19 -> 0 | I19: 0 | J19: =F19*I19 -> 0 | K19: =G19+I19 -> 200000 | L19: =F19*K19 -> 0
A20: 허가 | B20: 공사동의서 및 행위허가 | E20: 식 | F20: 1 | G20: 800000 | H20: =F20*G20 -> 800000 | I20: 0 | J20: =F20*I20 -> 0 | K20: =G20+I20 -> 800000 | L20: =F20*K20 -> 800000
A21: 가설 | B21: 엘리베이터 보양 | E21: 개소 | F21: 0 | G21: 200000 | H21: =F21*G21 -> 0 | I21: 0 | J21: =F21*I21 -> 0 | K21: =G21+I21 -> 200000 | L21: =F21*K21 -> 0
A22: 가설 | B22: 엘리베이터 사용료 | C22: 관리사무소 고객 직접 납부 | E22: 식 | F22: 0 | G22: 0 | H22: =F22*G22 -> 0 | I22: 0 | J22: =F22*I22 -> 0 | K22: =G22+I22 -> 0 | L22: =F22*K22 -> 0
A23: 보양 | B23: 엘리베이터 및 공용부 보양 | E23: 식 | F23: 0 | G23: 200000 | H23: =F23*G23 -> 0 | I23: 0 | J23: =F23*I23 -> 0 | K23: =G23+I23 -> 200000 | L23: =F23*K23 -> 0
A24: 폐기물 | B24: 페기물 반출 | C24: 1TON | E24: 대 | F24: 3 | G24: 500000 | H24: =F24*G24 -> 1500000 | I24: 100000 | J24: =F24*I24 -> 300000 | K24: =G24+I24 -> 600000 | L24: =F24*K24 -> 1800000 | N24: 10평에 1.1대
A26: 도어락 | B26: 디지털 도어락 | C26: 별도 | E26: M2 | F26: 0 | G26: 0 | H26: =F26*G26 -> 0 | I26: 0 | J26: =F26*I26 -> 0 | K26: =G26+I26 -> 0 | L26: =F26*K26 -> 0
A27: 인터폰 | B27: 인터폰 | C27: 별도 | E27: M2 | F27: 0 | G27: 0 | H27: =F27*G27 -> 0 | I27: 0 | J27: =F27*I27 -> 0 | K27: =G27+I27 -> 0 | L27: =F27*K27 -> 0
A28: 에어컨 | B28: 에어컨 | C28: 별도 | E28: 식 | F28: 0 | G28: 0 | H28: =F28*G28 -> 0 | I28: 0 | J28: =F28*I28 -> 0 | K28: =G28+I28 -> 0 | L28: =F28*K28 -> 0
A29: 환기 | B29: 전열교환기 | C29: 별도 | E29: 식 | F29: 0 | G29: 0 | H29: =F29*G29 -> 0 | I29: 1 | J29: =F29*I29 -> 0 | K29: =G29+I29 -> 1 | L29: =F29*K29 -> 0 | O29: =(155*0.05) -> 7.75
A30: 샷시 | B30: 창호 | C30: 별도 | E30: 식 | F30: 0 | G30: 0 | H30: =F30*G30 -> 0 | I30: 0 | J30: =F30*I30 -> 0 | K30: =G30+I30 -> 0 | L30: =F30*K30 -> 0
A31: 입주청소 | B31: 입주청소 | C31: 서비스 항목 | E31: M2 | F31: 0 | G31: 0 | H31: =F31*G31 -> 0 | I31: 0 | J31: =F31*I31 -> 0 | K31: =G31+I31 -> 0 | L31: =F31*K31 -> 0
B33: 소 계 | H33: =SUM(H16:H32) -> 2510000 | J33: =SUM(J16:J32) -> 1860000 | L33: =SUM(L16:L32) -> 4370000
A35: B. | B35: 인테리어 공사
A36: 1. | B36: 철거 공사 | E36: 식 | F36: 1 | H36: =H69 -> 1363000 | J36: =J69 -> 3551000 | L36: =L69 -> 4914000 | O36: =H36+J36 -> 4914000
A37: 2. | B37: 설비 공사 | E37: 식 | F37: 1 | H37: =H85 -> 1950000 | J37: =J85 -> 2800000 | L37: =L85 -> 4750000
A38: 3. | B38: =B87 -> 필름 공사 | E38: 식 | F38: 1 | H38: =H98 -> 946000 | J38: =J98 -> 2031000 | L38: =L98 -> 2977000 | O38: =H38+J38 -> 2977000
A39: 4. | B39: =B100 -> 가구 공사 | E39: 식 | F39: 1 | H39: =H170 -> 7919500 | J39: =J170 -> 1586000 | L39: =L170 -> 9505500 | O39: =H39+J39 -> 9505500
A40: 5. | B40: =B171 -> 전기 공사 | E40: 식 | F40: 1 | H40: =H189 -> 2376000 | J40: =J189 -> 2235000 | L40: =L189 -> 4611000 | O40: =H40+J40 -> 4611000
A41: 6. | B41: =B191 -> 화장실 공사 | E41: 식 | F41: 1 | H41: =H226 -> 3362000 | J41: =J226 -> 1310000 | L41: =L226 -> 4652000 | O41: =H41+J41 -> 4672000
A42: 7. | B42: =B228 -> 타일 공사 | E42: 식 | F42: 1 | H42: =H272 -> 3182000 | J42: =J272 -> 3498000 | L42: =L272 -> 6680000 | O42: =H42+J42 -> 6680000
A43: 8. | B43: =B274 -> 도배 공사 | E43: 식 | F43: 1 | H43: =H281 -> 1716000 | J43: =J281 -> 3120000 | L43: =L281 -> 4836000 | O43: =H43+J43 -> 4836000
A44: 9. | B44: =B283 -> 도장 공사 | E44: 식 | F44: 1 | H44: =H294 -> 600000 | J44: =J294 -> 750000 | L44: =L294 -> 1350000 | O44: =H44+J44 -> 1350000
A45: 10. | B45: =B296 -> 마루 공사 | E45: 식 | F45: 1 | H45: =H306 -> 2645000 | J45: =J306 -> 575000 | L45: =L306 -> 3220000 | O45: =H45+J45 -> 3220000
A46: 11. | B46: =B308 -> 목공사 | E46: 식 | F46: 1 | H46: =H365 -> 5880000 | J46: =J365 -> 6625000 | L46: =L365 -> 12505000 | O46: =H46+J46 -> 12505000
B48: 소 계 | H48: =SUM(H36:H47) -> 31939500 | J48: =SUM(J36:J47) -> 28081000 | L48: =SUM(L36:L47) -> 60000500
A51: 1. | B51: 철거 공사 | N51: 실행 금액
A52: 철거 | B52: 마루 철거 | C52: 공용부 | E52: PY | F52: 0 | G52: 8800 | H52: =F52*G52 -> 0 | I52: 18700 | J52: =F52*I52 -> 0 | K52: =G52+I52 -> 27500 | L52: =F52*K52 -> 0 | N52: 1400000 | Q52: 68
A53: 철거 | B53: 장판철거 | C53: 방 전체 | E53: PY | F53: 26 | G53: 3000 | H53: =F53*G53 -> 78000 | I53: 8500 | J53: =F53*I53 -> 221000 | K53: =G53+I53 -> 11500 | L53: =F53*K53 -> 299000 | N53: 1400000 | Q53: 68
...
